Workbook

Sheet Fases e Atividades
B1: [*] Campos de Preenchimento Obrigatório [+] Campos de Preenchimento Opcional [=] Campos com Fórmula | L1: [*] Campos de Preenchimento Obrigatório [+] Campos de Preenchimento Opcional [=] Campos com Fórmula
B3: FASES E ATIVIDADES
B5: Fases, Esforço e Previsão de Início e Término | L5: Atividades, Esforço e Previsão de Início e Término
B6: ( i ) As fases do projeto são as partes de maior hierarquia e as mais distantes do operacional. Abaixo delas há atividades e, mais abaixo, tarefas. Cadastre as fases do projeto. | L6: ( i ) Atividades pertencem a fases e permitem dividi-las em partes menores. Dessa forma elas estão mais próximas do operacional. Cadastre as atividades de cada fase.
B7: TOTAL: | C7: =COUNTA(TB_FASES[Fase '[*']]) & " DE 50" -> 4 DE 50 | D7: TOTAL COM ATRASO: | F7: =_xlfn.LET(_xlpm.total,COUNTA(TB_FASES[Fase '[*']]),_xlpm.totalAtraso,COUNTIF(TB_FASES[Status '[=']],"*ATRASO*"),_xlpm.totalAtraso & IF(_xlpm.total>0," (" & TEXT(_xlpm.totalAtraso/_xlpm.total,"0,0%")&")","")) -> 4 (100,0%) | L7: TOTAL: | M7: =COUNTA(TB_ATIVIDADES[Atividade '[*']]) & " DE 250" -> 20 DE 250 | N7: TOTAL COM ATRASO: | Q7: =_xlfn.LET(_xlpm.total,COUNTA(TB_ATIVIDADES[Atividade '[*']]),_xlpm.totalAtraso,COUNTIF(TB_ATIVIDADES[Status '[=']],"*ATRASO*"),_xlpm.totalAtraso & IF(_xlpm.total>0," (" & TEXT(_xlpm.totalAtraso/_xlpm.total,"0,0%")&")","")) -> 17 (85,0%)
B8: Fase [*] | C8: Total Atividades [=] | D8: Total Tarefas [=] | E8: Total Ativ. Não Concluídas [=] | F8: Esforço Total (min) [=] | G8: Esforço Restante (min) [=] | H8: Previsão Início [=] | I8: Previsão Conclusão [=] | J8: Status [=] | L8: Atividade [*] | M8: Fase [*] | N8: Total Tarefas [=] | O8: Total Tar. Não Concluídas [=] | P8: Esforço Total (min) [=] | Q8: Esforço Restante (min) [=] | R8: Previsão Início [=] | S8: Previsão Conclusão [=] | T8: Status [=]
B9: F1-DESENV | C9: =IF(TB_FASES[[#This Row],[Fase '[*']]]="","-",COUNTIF(TB_ATIVIDADES[Fase '[*']],TB_FASES[[#This Row],[Fase '[*']]])) -> 15 | D9: =IF(TB_FASES[[#This Row],[Fase '[*']]]="","-",SUMIF(TB_ATIVIDADES[Fase '[*']],TB_FASES[[#This Row],[Fase '[*']]],TB_ATIVIDADES[Total Tarefas '[=']])) -> 80 | E9: =IF(TB_FASES[[#This Row],[Fase '[*']]]="","-",_xlfn.LET(_xlpm.tot,COUNTIFS(TB_ATIVIDADES[Fase '[*']],TB_FASES[[#This Row],[Fase '[*']]],TB_ATIVIDADES[Status '[=']],"<>" & "CONCLUÍDA"),_xlpm.tot & IF(TB_FASES[[#This Row],[Total Atividades '[=']]]=0,""," (" & TEXT(_xlpm.tot/TB_FASES[[#This Row],[Total Atividades '[=']]],"0,0%") & ")"))) -> 12 (80,0%) | F9: =IF(TB_FASES[[#This Row],[Fase '[*']]]="","-",SUMIF(TB_ATIVIDADES[Fase '[*']],TB_FASES[[#This Row],[Fase '[*']]],TB_ATIVIDADES[Esforço Total (min) '[=']])) -> 1970 | G9: =IF(TB_FASES[[#This Row],[Fase '[*']]]="","-",_xlfn.LET(_xlpm.esforcoRealizado,SUMIFS(TB_TAREFAS[Previsão Esforço (min) '[*']],TB_TAREFAS[Fase '[=']],TB_FASES[[#This Row],[Fase '[*']]],TB_TAREFAS[Situação da Execução '[*']],"CONCLUÍDA"),(TB_FASES[[#This Row],[Esforço Total (min) '[=']]]-_xlpm.esforcoRealizado) & IF(TB_FASES[[#This Row],[Esforço Total (min) '[=']]]>0," ("&TEXT((TB_FASES[[#This Row],[Esforço Total (min) '[=']]]-_xlpm.esforcoRealizado)/TB_FASES[[#This Row],[Esforço Total (min) '[=']]],"0,0%")&")",""))) -> 1710 (86,8%) | H9: =IF(TB_FASES[[#This Row],[Fase '[*']]]="","-",_xlfn.LET(_xlpm.dataMin,_xlfn.MINIFS(TB_ATIVIDADES[Previsão Início '[=']],TB_ATIVIDADES[Fase '[*']],TB_FASES[[#This Row],[Fase '[*']]]),IF(_xlpm.dataMin=DATE(1900,1,0),"Indefinida",_xlpm.dataMin))) -> 46083 | I9: =IF(TB_FASES[[#This Row],[Fase '[*']]]="","-",_xlfn.LET(_xlpm.dataMax,_xlfn.MAXIFS(TB_ATIVIDADES[Previsão Conclusão '[=']],TB_ATIVIDADES[Fase '[*']],TB_FASES[[#This Row],[Fase '[*']]]),IF(_xlpm.dataMax=DATE(1900,1,0),"Indefinida",_xlpm.dataMax))) -> 46103 | J9: =IF(TB_FASES[[#This Row],[Fase '[*']]]="","-",IF(TB_FASES[[#This Row],[Total Atividades '[=']]]=0,"-",_xlfn.LET(_xlpm.totAtivNaoConcluidas,COUNTIFS(TB_ATIVIDADES[Fase '[*']],TB_FASES[[#This Row],[Fase '[*']]],TB_ATIVIDADES[Status '[=']],"<>" & "CONCLUÍDA"),_xlpm.totAtivConcluidas,TB_FASES[[#This Row],[Total Atividades '[=']]]-_xlpm.totAtivNaoConcluidas,_xlpm.totAtivNaoIniciadas,COUNTIFS(TB_ATIVIDADES[Fase '[*']],TB_FASES[[#This Row],[Fase '[*']]],TB_ATIVIDADES[Status '[=']],"NÃO INICIADA")+COUNTIFS(TB_ATIVIDADES[Fase '[*']],TB_FASES[[#This Row],[Fase '[*']]],TB_ATIVIDADES[Status '[=']],"INÍCIO COM ATRASO"),IF(_xlpm.totAtivConcluidas=TB_FASES[[#This Row],[Total Atividades '[=']]],"CONCLUÍDA",IF(_xlpm.totAtivNaoIniciadas=TB_FASES[[#This Row],[Total Atividades '[=']]],IF(AND(DATE(YEAR(NOW()),MONTH(NOW()),DAY(NOW())) > IFERROR(DATE(YEAR(TB_FASES[[#This Row],[Previsão Início '[=']]]),MONTH(TB_FASES[[#This Row],[Previsão Início '[=']]]),DAY(TB_FASES[[#This Row],[Previsão Início '[=']]])),FALSE)),"INICIO COM ATRASO","NÃO INICIADA"),IF(AND(DATE(YEAR(NOW()),MONTH(NOW()),DAY(NOW())) > IFERROR(DATE(YEAR(TB_FASES[[#This Row],[Previsão Conclusão '[=']]]),MONTH(TB_FASES[[#This Row],[Previsão Conclusão '[=']]]),DAY(TB_FASES[[#This Row],[Previsão Conclusão '[=']]])),FALSE)),"CONCLUSÃO COM ATRASO","EM ANDAMENTO")))))) -> CONCLUSÃO COM ATRASO | L9: Desenv. Pg. Home | M9: F1-DESENV | N9: =IF(OR(TB_ATIVIDADES[[#This Row],[Atividade '[*']]]="",TB_ATIVIDADES[[#This Row],[Fase '[*']]]=""),"-",COUNTIF(TB_TAREFAS[Atividade '[*']],TB_ATIVIDADES[[#This Row],[Atividade '[*']]])) -> 5 | O9: =IF(OR(TB_ATIVIDADES[[#This Row],[Atividade '[*']]]="",TB_ATIVIDADES[[#This Row],[Fase '[*']]]=""),"-",_xlfn.LET(_xlpm.tot,COUNTIFS(TB_TAREFAS[Atividade '[*']],TB_ATIVIDADES[[#This Row],[Atividade '[*']]],TB_TAREFAS[Situação da Execução '[*']],"<>" & "CONCLUÍDA",TB_TAREFAS[Situação da Execução '[*']],"<>"&"DESNECESSÁRIA"),_xlpm.tot & IF(TB_ATIVIDADES[[#This Row],[Total Tarefas '[=']]]=0,""," (" & TEXT(_xlpm.tot/TB_ATIVIDADES[[#This Row],[Total Tarefas '[=']]],"0,0%") & ")"))) -> 0 (0,0%) | P9: =IF(OR(TB_ATIVIDADES[[#This Row],[Atividade '[*']]]="",TB_ATIVIDADES[[#This Row],[Fase '[*']]]=""),"-",SUMIF(TB_TAREFAS[Atividade '[*']],TB_ATIVIDADES[[#This Row],[Atividade '[*']]],TB_TAREFAS[Previsão Esforço (min) '[*']])) -> 95 | Q9: =IF(OR(TB_ATIVIDADES[[#This Row],[Atividade '[*']]]="",TB_ATIVIDADES[[#This Row],[Fase '[*']]]=""),"-",_xlfn.LET(_xlpm.esforçoRealizado,SUMIFS(TB_TAREFAS[Previsão Esforço (min) '[*']],TB_TAREFAS[Atividade '[*']],TB_ATIVIDADES[[#This Row],[Atividade '[*']]],TB_TAREFAS[Situação da Execução '[*']],"CONCLUÍDA")+SUMIFS(TB_TAREFAS[Previsão Esforço (min) '[*']],TB_TAREFAS[Atividade '[*']],TB_ATIVIDADES[[#This Row],[Atividade '[*']]],TB_TAREFAS[Situação da Execução '[*']],"DESNECESSÁRIA"),TB_ATIVIDADES[[#This Row],[Esforço Total (min) '[=']]]-_xlpm.esforçoRealizado & IF(TB_ATIVIDADES[[#This Row],[Esforço Total (min) '[=']]]=0,""," (" & TEXT((TB_ATIVIDADES[[#This Row],[Esforço Total (min) '[=']]]-_xlpm.esforçoRealizado) / TB_ATIVIDADES[[#This Row],[Esforço Total (min) '[=']]],"0,0%") & ")"))) -> 0 (0,0%) | R9: =IF(OR(TB_ATIVIDADES[[#This Row],[Atividade '[*']]]="",TB_ATIVIDADES[[#This Row],[Fase '[*']]]=""),"-",_xlfn.LET(_xlpm.dataMin,_xlfn.MINIFS(TB_TAREFAS[Previsão Início '[*']],TB_TAREFAS[Atividade '[*']],TB_ATIVIDADES[[#This Row],[Atividade '[*']]]),IF(_xlpm.dataMin=0,"-",_xlpm.dataMin))) -> 46083 | S9: =IF(OR(TB_ATIVIDADES[[#This Row],[Atividade '[*']]]="",TB_ATIVIDADES[[#This Row],[Fase '[*']]]=""),"-",_xlfn.LET(_xlpm.dataMax,_xlfn.MAXIFS(TB_TAREFAS[Previsão Conclusão '[*']],TB_TAREFAS[Atividade '[*']],TB_ATIVIDADES[[#This Row],[Atividade '[*']]]),IF(_xlpm.dataMax=0,"-",_xlpm.dataMax))) -> 46083 | T9: =IF(OR(TB_ATIVIDADES[[#This Row],[Atividade '[*']]]="",TB_ATIVIDADES[[#This Row],[Fase '[*']]]=""),"-",IF(TB_ATIVIDADES[[#This Row],[Total Tarefas '[=']]]=0,"-",_xlfn.LET(_xlpm.totItensNaoConcluidos,COUNTIFS(TB_TAREFAS[Atividade '[*']],TB_ATIVIDADES[[#This Row],[Atividade '[*']]],TB_TAREFAS[Situação da Execução '[*']],"<>" & "CONCLUÍDA",TB_TAREFAS[Situação da Execução '[*']],"<>" & "DESNECESSÁRIA"),_xlpm.totItensConcluidos,TB_ATIVIDADES[[#This Row],[Total Tarefas '[=']]]-_xlpm.totItensNaoConcluidos,_xlpm.totItensNaoIniciados,COUNTIFS(TB_TAREFAS[Atividade '[*']],TB_ATIVIDADES[[#This Row],[Atividade '[*']]],TB_TAREFAS[Situação da Execução '[*']],"NÃO INICIADA"),IF(_xlpm.totItensConcluidos=TB_ATIVIDADES[[#This Row],[Total Tarefas '[=']]],"CONCLUÍDA",IF(_xlpm.totItensNaoIniciados=TB_ATIVIDADES[[#This Row],[Total Tarefas '[=']]],IF(AND(DATE(YEAR(NOW()),MONTH(NOW()),DAY(NOW())) > IFERROR(DATE(YEAR(TB_ATIVIDADES[[#This Row],[Previsão Início '[=']]]),MONTH(TB_ATIVIDADES[[#This Row],[Previsão Início '[=']]]),DAY(TB_ATIVIDADES[[#This Row],[Previsão Início '[=']]])),FALSE)),"INÍCIO COM ATRASO","NÃO INICIADA"),IF(AND(DATE(YEAR(NOW()),MONTH(NOW()),DAY(NOW())) > IFERROR(DATE(YEAR(TB_ATIVIDADES[[#This Row],[Previsão Conclusão '[=']]]),MONTH(TB_ATIVIDADES[[#This Row],[Previsão Conclusão '[=']]]),DAY(TB_ATIVIDADES[[#This Row],[Previsão Conclusão '[=']]])),FALSE)),"CONCLUSÃO COM ATRASO","EM ANDAMENTO")))))) -> CONCLUÍDA
B10: F2-TESTE | C10: =IF(TB_FASES[[#This Row],[Fase '[*']]]="","-",COUNTIF(TB_ATIVIDADES[Fase '[*']],TB_FASES[[#This Row],[Fase '[*']]])) -> 1 | D10: =IF(TB_FASES[[#This Row],[Fase '[*']]]="","-",SUMIF(TB_ATIVIDADES[Fase '[*']],TB_FASES[[#This Row],[Fase '[*']]],TB_ATIVIDADES[Total Tarefas '[=']])) -> 4 | E10: =IF(TB_FASES[[#This Row],[Fase '[*']]]="","-",_xlfn.LET(_xlpm.tot,COUNTIFS(TB_ATIVIDADES[Fase '[*']],TB_FASES[[#This Row],[Fase '[*']]],TB_ATIVIDADES[Status '[=']],"<>" & "CONCLUÍDA"),_xlpm.tot & IF(TB_FASES[[#This Row],[Total Atividades '[=']]]=0,""," (" & TEXT(_xlpm.tot/TB_FASES[[#This Row],[Total Atividades '[=']]],"0,0%") & ")"))) -> 1 (100,0%) | F10: =IF(TB_FASES[[#This Row],[Fase '[*']]]="","-",SUMIF(TB_ATIVIDADES[Fase '[*']],TB_FASES[[#This Row],[Fase '[*']]],TB_ATIVIDADES[Esforço Total (min) '[=']])) -> 420 | G10: =IF(TB_FASES[[#This Row],[Fase '[*']]]="","-",_xlfn.LET(_xlpm.esforcoRealizado,SUMIFS(TB_TAREFAS[Previsão Esforço (min) '[*']],TB_TAREFAS[Fase '[=']],TB_FASES[[#This Row],[Fase '[*']]],TB_TAREFAS[Situação da Execução '[*']],"CONCLUÍDA"),(TB_FASES[[#This Row],[Esforço Total (min) '[=']]]-_xlpm.esforcoRealizado) & IF(TB_FASES[[#This Row],[Esforço Total (min) '[=']]]>0," ("&TEXT((TB_FASES[[#This Row],[Esforço Total (min) '[=']]]-_xlpm.esforcoRealizado)/TB_FASES[[#This Row],[Esforço Total (min) '[=']]],"0,0%")&")",""))) -> 420 (100,0%) | H10: =IF(TB_FASES[[#This Row],[Fase '[*']]]="","-",_xlfn.LET(_xlpm.dataMin,_xlfn.MINIFS(TB_ATIVIDADES[Previsão Início '[=']],TB_ATIVIDADES[Fase '[*']],TB_FASES[[#This Row],[Fase '[*']]]),IF(_xlpm.dataMin=DATE(1900,1,0),"Indefinida",_xlpm.dataMin))) -> 46092 | I10: =IF(TB_FASES[[#This Row],[Fase '[*']]]="","-",_xlfn.LET(_xlpm.dataMax,_xlfn.MAXIFS(TB_ATIVIDADES[Previsão Conclusão '[=']],TB_ATIVIDADES[Fase '[*']],TB_FASES[[#This Row],[Fase '[*']]]),IF(_xlpm.dataMax=DATE(1900,1,0),"Indefinida",_xlpm.dataMax))) -> 46093 | J10: =IF(TB_FASES[[#This Row],[Fase '[*']]]="","-",IF(TB_FASES[[#This Row],[Total Atividades '[=']]]=0,"-",_xlfn.LET(_xlpm.totAtivNaoConcluidas,COUNTIFS(TB_ATIVIDADES[Fase '[*']],TB_FASES[[#This Row],[Fase '[*']]],TB_ATIVIDADES[Status '[=']],"<>" & "CONCLUÍDA"),_xlpm.totAtivConcluidas,TB_FASES[[#This Row],[Total Atividades '[=']]]-_xlpm.totAtivNaoConcluidas,_xlpm.totAtivNaoIniciadas,COUNTIFS(TB_ATIVIDADES[Fase '[*']],TB_FASES[[#This Row],[Fase '[*']]],TB_ATIVIDADES[Status '[=']],"NÃO INICIADA")+COUNTIFS(TB_ATIVIDADES[Fase '[*']],TB_FASES[[#This Row],[Fase '[*']]],TB_ATIVIDADES[Status '[=']],"INÍCIO COM ATRASO"),IF(_xlpm.totAtivConcluidas=TB_FASES[[#This Row],[Total Atividades '[=']]],"CONCLUÍDA",IF(_xlpm.totAtivNaoIniciadas=TB_FASES[[#This Row],[Total Atividades '[=']]],IF(AND(DATE(YEAR(NOW()),MONTH(NOW()),DAY(NOW())) > IFERROR(DATE(YEAR(TB_FASES[[#This Row],[Previsão Início '[=']]]),MONTH(TB_FASES[[#This Row],[Previsão Início '[=']]]),DAY(TB_FASES[[#This Row],[Previsão Início '[=']]])),FALSE)),"INICIO COM ATRASO","NÃO INICIADA"),IF(AND(DATE(YEAR(NOW()),MONTH(NOW()),DAY(NOW())) > IFERROR(DATE(YEAR(TB_FASES[[#This Row],[Previsão Conclusão '[=']]]),MONTH(TB_FASES[[#This Row],[Previsão Conclusão '[=']]]),DAY(TB_FASES[[#This Row],[Previsão Conclusão '[=']]])),FALSE)),"CONCLUSÃO COM ATRASO","EM ANDAMENTO")))))) -> INICIO COM ATRASO | L10: Desenv. Pg. Cadastro | M10: F1-DESENV | N10: =IF(OR(TB_ATIVIDADES[[#This Row],[Atividade '[*']]]="",TB_ATIVIDADES[[#This Row],[Fase '[*']]]=""),"-",COUNTIF(TB_TAREFAS[Atividade '[*']],TB_ATIVIDADES[[#This Row],[Atividade '[*']]])) -> 7 | O10: =IF(OR(TB_ATIVIDADES[[#This Row],[Atividade '[*']]]="",TB_ATIVIDADES[[#This Row],[Fase '[*']]]=""),"-",_xlfn.LET(_xlpm.tot,COUNTIFS(TB_TAREFAS[Atividade '[*']],TB_ATIVIDADES[[#This Row],[Atividade '[*']]],TB_TAREFAS[Situação da Execução '[*']],"<>" & "CONCLUÍDA",TB_TAREFAS[Situação da Execução '[*']],"<>"&"DESNECESSÁRIA"),_xlpm.tot & IF(TB_ATIVIDADES[[#This Row],[Total Tarefas '[=']]]=0,""," (" & TEXT(_xlpm.tot/TB_ATIVIDADES[[#This Row],[Total Tarefas '[=']]],"0,0%") & ")"))) -> 0 (0,0%) | P10: =IF(OR(TB_ATIVIDADES[[#This Row],[Atividade '[*']]]="",TB_ATIVIDADES[[#This Row],[Fase '[*']]]=""),"-",SUMIF(TB_TAREFAS[Atividade '[*']],TB_ATIVIDADES[[#This Row],[Atividade '[*']]],TB_TAREFAS[Previsão Esforço (min) '[*']])) -> 125 | Q10: =IF(OR(TB_ATIVIDADES[[#This Row],[Atividade '[*']]]="",TB_ATIVIDADES[[#This Row],[Fase '[*']]]=""),"-",_xlfn.LET(_xlpm.esforçoRealizado,SUMIFS(TB_TAREFAS[Previsão Esforço (min) '[*']],TB_TAREFAS[Atividade '[*']],TB_ATIVIDADES[[#This Row],[Atividade '[*']]],TB_TAREFAS[Situação da Execução '[*']],"CONCLUÍDA")+SUMIFS(TB_TAREFAS[Previsão Esforço (min) '[*']],TB_TAREFAS[Atividade '[*']],TB_ATIVIDADES[[#This Row],[Atividade '[*']]],TB_TAREFAS[Situação da Execução '[*']],"DESNECESSÁRIA"),TB_ATIVIDADES[[#This Row],[Esforço Total (min) '[=']]]-_xlpm.esforçoRealizado & IF(TB_ATIVIDADES[[#This Row],[Esforço Total (min) '[=']]]=0,""," (" & TEXT((TB_ATIVIDADES[[#This Row],[Esforço Total (min) '[=']]]-_xlpm.esforçoRealizado) / TB_ATIVIDADES[[#This Row],[Esforço Total (min) '[=']]],"0,0%") & ")"))) -> 0 (0,0%) | R10: =IF(OR(TB_ATIVIDADES[[#This Row],[Atividade '[*']]]="",TB_ATIVIDADES[[#This Row],[Fase '[*']]]=""),"-",_xlfn.LET(_xlpm.dataMin,_xlfn.MINIFS(TB_TAREFAS[Previsão Início '[*']],TB_TAREFAS[Atividade '[*']],TB_ATIVIDADES[[#This Row],[Atividade '[*']]]),IF(_xlpm.dataMin=0,"-",_xlpm.dataMin))) -> 46083 | S10: =IF(OR(TB_ATIVIDADES[[#This Row],[Atividade '[*']]]="",TB_ATIVIDADES[[#This Row],[Fase '[*']]]=""),"-",_xlfn.LET(_xlpm.dataMax,_xlfn.MAXIFS(TB_TAREFAS[Previsão Conclusão '[*']],TB_TAREFAS[Atividade '[*']],TB_ATIVIDADES[[#This Row],[Atividade '[*']]]),IF(_xlpm.dataMax=0,"-",_xlpm.dataMax))) -> 46083 | T10: =IF(OR(TB_ATIVIDADES[[#This Row],[Atividade '[*']]]="",TB_ATIVIDADES[[#This Row],[Fase '[*']]]=""),"-",IF(TB_ATIVIDADES[[#This Row],[Total Tarefas '[=']]]=0,"-",_xlfn.LET(_xlpm.totItensNaoConcluidos,COUNTIFS(TB_TAREFAS[Atividade '[*']],TB_ATIVIDADES[[#This Row],[Atividade '[*']]],TB_TAREFAS[Situação da Execução '[*']],"<>" & "CONCLUÍDA",TB_TAREFAS[Situação da Execução '[*']],"<>" & "DESNECESSÁRIA"),_xlpm.totItensConcluidos,TB_ATIVIDADES[[#This Row],[Total Tarefas '[=']]]-_xlpm.totItensNaoConcluidos,_xlpm.totItensNaoIniciados,COUNTIFS(TB_TAREFAS[Atividade '[*']],TB_ATIVIDADES[[#This Row],[Atividade '[*']]],TB_TAREFAS[Situação da Execução '[*']],"NÃO INICIADA"),IF(_xlpm.totItensConcluidos=TB_ATIVIDADES[[#This Row],[Total Tarefas '[=']]],"CONCLUÍDA",IF(_xlpm.totItensNaoIniciados=TB_ATIVIDADES[[#This Row],[Total Tarefas '[=']]],IF(AND(DATE(YEAR(NOW()),MONTH(NOW()),DAY(NOW())) > IFERROR(DATE(YEAR(TB_ATIVIDADES[[#This Row],[Previsão Início '[=']]]),MONTH(TB_ATIVIDADES[[#This Row],[Previsão Início '[=']]]),DAY(TB_ATIVIDADES[[#This Row],[Previsão Início '[=']]])),FALSE)),"INÍCIO COM ATRASO","NÃO INICIADA"),IF(AND(DATE(YEAR(NOW()),MONTH(NOW()),DAY(NOW())) > IFERROR(DATE(YEAR(TB_ATIVIDADES[[#This Row],[Previsão Conclusão '[=']]]),MONTH(TB_ATIVIDADES[[#This Row],[Previsão Conclusão '[=']]]),DAY(TB_ATIVIDADES[[#This Row],[Previsão Conclusão '[=']]])),FALSE)),"CONCLUSÃO COM ATRASO","EM ANDAMENTO")))))) -> CONCLUÍDA
B11: F3-LIBERAÇÃO | C11: =IF(TB_FASES[[#This Row],[Fase '[*']]]="","-",COUNTIF(TB_ATIVIDADES[Fase '[*']],TB_FASES[[#This Row],[Fase '[*']]])) -> 3 | D11: =IF(TB_FASES[[#This Row],[Fase '[*']]]="","-",SUMIF(TB_ATIVIDADES[Fase '[*']],TB_FASES[[#This Row],[Fase '[*']]],TB_ATIVIDADES[Total Tarefas '[=']])) -> 9 | E11: =IF(TB_FASES[[#This Row],[Fase '[*']]]="","-",_xlfn.LET(_xlpm.tot,COUNTIFS(TB_ATIVIDADES[Fase '[*']],TB_FASES[[#This Row],[Fase '[*']]],TB_ATIVIDADES[Status '[=']],"<>" & "CONCLUÍDA"),_xlpm.tot & IF(TB_FASES[[#This Row],[Total Atividades '[=']]]=0,""," (" & TEXT(_xlpm.tot/TB_FASES[[#This Row],[Total Atividades '[=']]],"0,0%") & ")"))) -> 3 (100,0%) | F11: =IF(TB_FASES[[#This Row],[Fase '[*']]]="","-",SUMIF(TB_ATIVIDADES[Fase '[*']],TB_FASES[[#This Row],[Fase '[*']]],TB_ATIVIDADES[Esforço Total (min) '[=']])) -> 790 | G11: =IF(TB_FASES[[#This Row],[Fase '[*']]]="","-",_xlfn.LET(_xlpm.esforcoRealizado,SUMIFS(TB_TAREFAS[Previsão Esforço (min) '[*']],TB_TAREFAS[Fase '[=']],TB_FASES[[#This Row],[Fase '[*']]],TB_TAREFAS[Situação da Execução '[*']],"CONCLUÍDA"),(TB_FASES[[#This Row],[Esforço Total (min) '[=']]]-_xlpm.esforcoRealizado) & IF(TB_FASES[[#This Row],[Esforço Total (min) '[=']]]>0," ("&TEXT((TB_FASES[[#This Row],[Esforço Total (min) '[=']]]-_xlpm.esforcoRealizado)/TB_FASES[[#This Row],[Esforço Total (min) '[=']]],"0,0%")&")",""))) -> 790 (100,0%) | H11: =IF(TB_FASES[[#This Row],[Fase '[*']]]="","-",_xlfn.LET(_xlpm.dataMin,_xlfn.MINIFS(TB_ATIVIDADES[Previsão Início '[=']],TB_ATIVIDADES[Fase '[*']],TB_FASES[[#This Row],[Fase '[*']]]),IF(_xlpm.dataMin=DATE(1900,1,0),"Indefinida",_xlpm.dataMin))) -> 46093 | I11: =IF(TB_FASES[[#This Row],[Fase '[*']]]="","-",_xlfn.LET(_xlpm.dataMax,_xlfn.MAXIFS(TB_ATIVIDADES[Previsão Conclusão '[=']],TB_ATIVIDADES[Fase '[*']],TB_FASES[[#This Row],[Fase '[*']]]),IF(_xlpm.dataMax=DATE(1900,1,0),"Indefinida",_xlpm.dataMax))) -> 46097 | J11: =IF(TB_FASES[[#This Row],[Fase '[*']]]="","-",IF(TB_FASES[[#This Row],[Total Atividades '[=']]]=0,"-",_xlfn.LET(_xlpm.totAtivNaoConcluidas,COUNTIFS(TB_ATIVIDADES[Fase '[*']],TB_FASES[[#This Row],[Fase '[*']]],TB_ATIVIDADES[Status '[=']],"<>" & "CONCLUÍDA"),_xlpm.totAtivConcluidas,TB_FASES[[#This Row],[Total Atividades '[=']]]-_xlpm.totAtivNaoConcluidas,_xlpm.totAtivNaoIniciadas,COUNTIFS(TB_ATIVIDADES[Fase '[*']],TB_FASES[[#This Row],[Fase '[*']]],TB_ATIVIDADES[Status '[=']],"NÃO INICIADA")+COUNTIFS(TB_ATIVIDADES[Fase '[*']],TB_FASES[[#This Row],[Fase '[*']]],TB_ATIVIDADES[Status '[=']],"INÍCIO COM ATRASO"),IF(_xlpm.totAtivConcluidas=TB_FASES[[#This Row],[Total Atividades '[=']]],"CONCLUÍDA",IF(_xlpm.totAtivNaoIniciadas=TB_FASES[[#This Row],[Total Atividades '[=']]],IF(AND(DATE(YEAR(NOW()),MONTH(NOW()),DAY(NOW())) > IFERROR(DATE(YEAR(TB_FASES[[#This Row],[Previsão Início '[=']]]),MONTH(TB_FASES[[#This Row],[Previsão Início '[=']]]),DAY(TB_FASES[[#This Row],[Previsão Início '[=']]])),FALSE)),"INICIO COM ATRASO","NÃO INICIADA"),IF(AND(DATE(YEAR(NOW()),MONTH(NOW()),DAY(NOW())) > IFERROR(DATE(YEAR(TB_FASES[[#This Row],[Previsão Conclusão '[=']]]),MONTH(TB_FASES[[#This Row],[Previsão Conclusão '[=']]]),DAY(TB_FASES[[#This Row],[Previsão Conclusão '[=']]])),FALSE)),"CONCLUSÃO COM ATRASO","EM ANDAMENTO")))))) -> INICIO COM ATRASO | L11: Desenv. Pg. Login | M11: F1-DESENV | N11: =IF(OR(TB_ATIVIDADES[[#This Row],[Atividade '[*']]]="",TB_ATIVIDADES[[#This Row],[Fase '[*']]]=""),"-",COUNTIF(TB_TAREFAS[Atividade '[*']],TB_ATIVIDADES[[#This Row],[Atividade '[*']]])) -> 4 | O11: =IF(OR(TB_ATIVIDADES[[#This Row],[Atividade '[*']]]="",TB_ATIVIDADES[[#This Row],[Fase '[*']]]=""),"-",_xlfn.LET(_xlpm.tot,COUNTIFS(TB_TAREFAS[Atividade '[*']],TB_ATIVIDADES[[#This Row],[Atividade '[*']]],TB_TAREFAS[Situação da Execução '[*']],"<>" & "CONCLUÍDA",TB_TAREFAS[Situação da Execução '[*']],"<>"&"DESNECESSÁRIA"),_xlpm.tot & IF(TB_ATIVIDADES[[#This Row],[Total Tarefas '[=']]]=0,""," (" & TEXT(_xlpm.tot/TB_ATIVIDADES[[#This Row],[Total Tarefas '[=']]],"0,0%") & ")"))) -> 0 (0,0%) | P11: =IF(OR(TB_ATIVIDADES[[#This Row],[Atividade '[*']]]="",TB_ATIVIDADES[[#This Row],[Fase '[*']]]=""),"-",SUMIF(TB_TAREFAS[Atividade '[*']],TB_ATIVIDADES[[#This Row],[Atividade '[*']]],TB_TAREFAS[Previsão Esforço (min) '[*']])) -> 65 | Q11: =IF(OR(TB_ATIVIDADES[[#This Row],[Atividade '[*']]]="",TB_ATIVIDADES[[#This Row],[Fase '[*']]]=""),"-",_xlfn.LET(_xlpm.esforçoRealizado,SUMIFS(TB_TAREFAS[Previsão Esforço (min) '[*']],TB_TAREFAS[Atividade '[*']],TB_ATIVIDADES[[#This Row],[Atividade '[*']]],TB_TAREFAS[Situação da Execução '[*']],"CONCLUÍDA")+SUMIFS(TB_TAREFAS[Previsão Esforço (min) '[*']],TB_TAREFAS[Atividade '[*']],TB_ATIVIDADES[[#This Row],[Atividade '[*']]],TB_TAREFAS[Situação da Execução '[*']],"DESNECESSÁRIA"),TB_ATIVIDADES[[#This Row],[Esforço Total (min) '[=']]]-_xlpm.esforçoRealizado & IF(TB_ATIVIDADES[[#This Row],[Esforço Total (min) '[=']]]=0,""," (" & TEXT((TB_ATIVIDADES[[#This Row],[Esforço Total (min) '[=']]]-_xlpm.esforçoRealizado) / TB_ATIVIDADES[[#This Row],[Esforço Total (min) '[=']]],"0,0%") & ")"))) -> 0 (0,0%) | R11: =IF(OR(TB_ATIVIDADES[[#This Row],[Atividade '[*']]]="",TB_ATIVIDADES[[#This Row],[Fase '[*']]]=""),"-",_xlfn.LET(_xlpm.dataMin,_xlfn.MINIFS(TB_TAREFAS[Previsão Início '[*']],TB_TAREFAS[Atividade '[*']],TB_ATIVIDADES[[#This Row],[Atividade '[*']]]),IF(_xlpm.dataMin=0,"-",_xlpm.dataMin))) -> 46083 | S11: =IF(OR(TB_ATIVIDADES[[#This Row],[Atividade '[*']]]="",TB_ATIVIDADES[[#This Row],[Fase '[*']]]=""),"-",_xlfn.LET(_xlpm.dataMax,_xlfn.MAXIFS(TB_TAREFAS[Previsão Conclusão '[*']],TB_TAREFAS[Atividade '[*']],TB_ATIVIDADES[[#This Row],[Atividade '[*']]]),IF(_xlpm.dataMax=0,"-",_xlpm.dataMax))) -> 46083 | T11: =IF(OR(TB_ATIVIDADES[[#This Row],[Atividade '[*']]]="",TB_ATIVIDADES[[#This Row],[Fase '[*']]]=""),"-",IF(TB_ATIVIDADES[[#This Row],[Total Tarefas '[=']]]=0,"-",_xlfn.LET(_xlpm.totItensNaoConcluidos,COUNTIFS(TB_TAREFAS[Atividade '[*']],TB_ATIVIDADES[[#This Row],[Atividade '[*']]],TB_TAREFAS[Situação da Execução '[*']],"<>" & "CONCLUÍDA",TB_TAREFAS[Situação da Execução '[*']],"<>" & "DESNECESSÁRIA"),_xlpm.totItensConcluidos,TB_ATIVIDADES[[#This Row],[Total Tarefas '[=']]]-_xlpm.totItensNaoConcluidos,_xlpm.totItensNaoIniciados,COUNTIFS(TB_TAREFAS[Atividade '[*']],TB_ATIVIDADES[[#This Row],[Atividade '[*']]],TB_TAREFAS[Situação da Execução '[*']],"NÃO INICIADA"),IF(_xlpm.totItensConcluidos=TB_ATIVIDADES[[#This Row],[Total Tarefas '[=']]],"CONCLUÍDA",IF(_xlpm.totItensNaoIniciados=TB_ATIVIDADES[[#This Row],[Total Tarefas '[=']]],IF(AND(DATE(YEAR(NOW()),MONTH(NOW()),DAY(NOW())) > IFERROR(DATE(YEAR(TB_ATIVIDADES[[#This Row],[Previsão Início '[=']]]),MONTH(TB_ATIVIDADES[[#This Row],[Previsão Início '[=']]]),DAY(TB_ATIVIDADES[[#This Row],[Previsão Início '[=']]])),FALSE)),"INÍCIO COM ATRASO","NÃO INICIADA"),IF(AND(DATE(YEAR(NOW()),MONTH(NOW()),DAY(NOW())) > IFERROR(DATE(YEAR(TB_ATIVIDADES[[#This Row],[Previsão Conclusão '[=']]]),MONTH(TB_ATIVIDADES[[#This Row],[Previsão Conclusão '[=']]]),DAY(TB_ATIVIDADES[[#This Row],[Previsão Conclusão '[=']]])),FALSE)),"CONCLUSÃO COM ATRASO","EM ANDAMENTO")))))) -> CONCLUÍDA
B12: F4-SUPORTE | C12: =IF(TB_FASES[[#This Row],[Fase '[*']]]="","-",COUNTIF(TB_ATIVIDADES[Fase '[*']],TB_FASES[[#This Row],[Fase '[*']]])) -> 1 | D12: =IF(TB_FASES[[#This Row],[Fase '[*']]]="","-",SUMIF(TB_ATIVIDADES[Fase '[*']],TB_FASES[[#This Row],[Fase '[*']]],TB_ATIVIDADES[Total Tarefas '[=']])) -> 1 | E12: =IF(TB_FASES[[#This Row],[Fase '[*']]]="","-",_xlfn.LET(_xlpm.tot,COUNTIFS(TB_ATIVIDADES[Fase '[*']],TB_FASES[[#This Row],[Fase '[*']]],TB_ATIVIDADES[Status '[=']],"<>" & "CONCLUÍDA"),_xlpm.tot & IF(TB_FASES[[#This Row],[Total Atividades '[=']]]=0,""," (" & TEXT(_xlpm.tot/TB_FASES[[#This Row],[Total Atividades '[=']]],"0,0%") & ")"))) -> 1 (100,0%) | F12: =IF(TB_FASES[[#This Row],[Fase '[*']]]="","-",SUMIF(TB_ATIVIDADES[Fase '[*']],TB_FASES[[#This Row],[Fase '[*']]],TB_ATIVIDADES[Esforço Total (min) '[=']])) -> 1770 | G12: =IF(TB_FASES[[#This Row],[Fase '[*']]]="","-",_xlfn.LET(_xlpm.esforcoRealizado,SUMIFS(TB_TAREFAS[Previsão Esforço (min) '[*']],TB_TAREFAS[Fase '[=']],TB_FASES[[#This Row],[Fase '[*']]],TB_TAREFAS[Situação da Execução '[*']],"CONCLUÍDA"),(TB_FASES[[#This Row],[Esforço Total (min) '[=']]]-_xlpm.esforcoRealizado) & IF(TB_FASES[[#This Row],[Esforço Total (min) '[=']]]>0," ("&TEXT((TB_FASES[[#This Row],[Esforço Total (min) '[=']]]-_xlpm.esforcoRealizado)/TB_FASES[[#This Row],[Esforço Total (min) '[=']]],"0,0%")&")",""))) -> 1770 (100,0%) | H12: =IF(TB_FASES[[#This Row],[Fase '[*']]]="","-",_xlfn.LET(_xlpm.dataMin,_xlfn.MINIFS(TB_ATIVIDADES[Previsão Início '[=']],TB_ATIVIDADES[Fase '[*']],TB_FASES[[#This Row],[Fase '[*']]]),IF(_xlpm.dataMin=DATE(1900,1,0),"Indefinida",_xlpm.dataMin))) -> 46118 | I12: =IF(TB_FASES[[#This Row],[Fase '[*']]]="","-",_xlfn.LET(_xlpm.dataMax,_xlfn.MAXIFS(TB_ATIVIDADES[Previsão Conclusão '[=']],TB_ATIVIDADES[Fase '[*']],TB_FASES[[#This Row],[Fase '[*']]]),IF(_xlpm.dataMax=DATE(1900,1,0),"Indefinida",_xlpm.dataMax))) -> 46177 | J12: =IF(TB_FASES[[#This Row],[Fase '[*']]]="","-",IF(TB_FASES[[#This Row],[Total Atividades '[=']]]=0,"-",_xlfn.LET(_xlpm.totAtivNaoConcluidas,COUNTIFS(TB_ATIVIDADES[Fase '[*']],TB_FASES[[#This Row],[Fase '[*']]],TB_ATIVIDADES[Status '[=']],"<>" & "CONCLUÍDA"),_xlpm.totAtivConcluidas,TB_FASES[[#This Row],[Total Atividades '[=']]]-_xlpm.totAtivNaoConcluidas,_xlpm.totAtivNaoIniciadas,COUNTIFS(TB_ATIVIDADES[Fase '[*']],TB_FASES[[#This Row],[Fase '[*']]],TB_ATIVIDADES[Status '[=']],"NÃO INICIADA")+COUNTIFS(TB_ATIVIDADES[Fase '[*']],TB_FASES[[#This Row],[Fase '[*']]],TB_ATIVIDADES[Status '[=']],"INÍCIO COM ATRASO"),IF(_xlpm.totAtivConcluidas=TB_FASES[[#This Row],[Total Atividades '[=']]],"CONCLUÍDA",IF(_xlpm.totAtivNaoIniciadas=TB_FASES[[#This Row],[Total Atividades '[=']]],IF(AND(DATE(YEAR(NOW()),MONTH(NOW()),DAY(NOW())) > IFERROR(DATE(YEAR(TB_FASES[[#This Row],[Previsão Início '[=']]]),MONTH(TB_FASES[[#This Row],[Previsão Início '[=']]]),DAY(TB_FASES[[#This Row],[Previsão Início '[=']]])),FALSE)),"INICIO COM ATRASO","NÃO INICIADA"),IF(AND(DATE(YEAR(NOW()),MONTH(NOW()),DAY(NOW())) > IFERROR(DATE(YEAR(TB_FASES[[#This Row],[Previsão Conclusão '[=']]]),MONTH(TB_FASES[[#This Row],[Previsão Conclusão '[=']]]),DAY(TB_FASES[[#This Row],[Previsão Conclusão '[=']]])),FALSE)),"CONCLUSÃO COM ATRASO","EM ANDAMENTO")))))) -> INICIO COM ATRASO | L12: Desenv. Pg. Bolões do Usuário | M12: F1-DESENV | N12: =IF(OR(TB_ATIVIDADES[[#This Row],[Atividade '[*']]]="",TB_ATIVIDADES[[#This Row],[Fase '[*']]]=""),"-",COUNTIF(TB_TAREFAS[Atividade '[*']],TB_ATIVIDADES[[#This Row],[Atividade '[*']]])) -> 7 | O12: =IF(OR(TB_ATIVIDADES[[#This Row],[Atividade '[*']]]="",TB_ATIVIDADES[[#This Row],[Fase '[*']]]=""),"-",_xlfn.LET(_xlpm.tot,COUNTIFS(TB_TAREFAS[Atividade '[*']],TB_ATIVIDADES[[#This Row],[Atividade '[*']]],TB_TAREFAS[Situação da Execução '[*']],"<>" & "CONCLUÍDA",TB_TAREFAS[Situação da Execução '[*']],"<>"&"DESNECESSÁRIA"),_xlpm.tot & IF(TB_ATIVIDADES[[#This Row],[Total Tarefas '[=']]]=0,""," (" & TEXT(_xlpm.tot/TB_ATIVIDADES[[#This Row],[Total Tarefas '[=']]],"0,0%") & ")"))) -> 7 (100,0%) | P12: =IF(OR(TB_ATIVIDADES[[#This Row],[Atividade '[*']]]="",TB_ATIVIDADES[[#This Row],[Fase '[*']]]=""),"-",SUMIF(TB_TAREFAS[Atividade '[*']],TB_ATIVIDADES[[#This Row],[Atividade '[*']]],TB_TAREFAS[Previsão Esforço (min) '[*']])) -> 225 | Q12: =IF(OR(TB_ATIVIDADES[[#This Row],[Atividade '[*']]]="",TB_ATIVIDADES[[#This Row],[Fase '[*']]]=""),"-",_xlfn.LET(_xlpm.esforçoRealizado,SUMIFS(TB_TAREFAS[Previsão Esforço (min) '[*']],TB_TAREFAS[Atividade '[*']],TB_ATIVIDADES[[#This Row],[Atividade '[*']]],TB_TAREFAS[Situação da Execução '[*']],"CONCLUÍDA")+SUMIFS(TB_TAREFAS[Previsão Esforço (min) '[*']],TB_TAREFAS[Atividade '[*']],TB_ATIVIDADES[[#This Row],[Atividade '[*']]],TB_TAREFAS[Situação da Execução '[*']],"DESNECESSÁRIA"),TB_ATIVIDADES[[#This Row],[Esforço Total (min) '[=']]]-_xlpm.esforçoRealizado & IF(TB_ATIVIDADES[[#This Row],[Esforço Total (min) '[=']]]=0,""," (" & TEXT((TB_ATIVIDADES[[#This Row],[Esforço Total (min) '[=']]]-_xlpm.esforçoRealizado) / TB_ATIVIDADES[[#This Row],[Esforço Total (min) '[=']]],"0,0%") & ")"))) -> 225 (100,0%) | R12: =IF(OR(TB_ATIVIDADES[[#This Row],[Atividade '[*']]]="",TB_ATIVIDADES[[#This Row],[Fase '[*']]]=""),"-",_xlfn.LET(_xlpm.dataMin,_xlfn.MINIFS(TB_TAREFAS[Previsão Início '[*']],TB_TAREFAS[Atividade '[*']],TB_ATIVIDADES[[#This Row],[Atividade '[*']]]),IF(_xlpm.dataMin=0,"-",_xlpm.dataMin))) -> 46084 | S12: =IF(OR(TB_ATIVIDADES[[#This Row],[Atividade '[*']]]="",TB_ATIVIDADES[[#This Row],[Fase '[*']]]=""),"-",_xlfn.LET(_xlpm.dataMax,_xlfn.MAXIFS(TB_TAREFAS[Previsão Conclusão '[*']],TB_TAREFAS[Atividade '[*']],TB_ATIVIDADES[[#This Row],[Atividade '[*']]]),IF(_xlpm.dataMax=0,"-",_xlpm.dataMax))) -> 46103 | T12: =IF(OR(TB_ATIVIDADES[[#This Row],[Atividade '[*']]]="",TB_ATIVIDADES[[#This Row],[Fase '[*']]]=""),"-",IF(TB_ATIVIDADES[[#This Row],[Total Tarefas '[=']]]=0,"-",_xlfn.LET(_xlpm.totItensNaoConcluidos,COUNTIFS(TB_TAREFAS[Atividade '[*']],TB_ATIVIDADES[[#This Row],[Atividade '[*']]],TB_TAREFAS[Situação da Execução '[*']],"<>" & "CONCLUÍDA",TB_TAREFAS[Situação da Execução '[*']],"<>" & "DESNECESSÁRIA"),_xlpm.totItensConcluidos,TB_ATIVIDADES[[#This Row],[Total Tarefas '[=']]]-_xlpm.totItensNaoConcluidos,_xlpm.totItensNaoIniciados,COUNTIFS(TB_TAREFAS[Atividade '[*']],TB_ATIVIDADES[[#This Row],[Atividade '[*']]],TB_TAREFAS[Situação da Execução '[*']],"NÃO INICIADA"),IF(_xlpm.totItensConcluidos=TB_ATIVIDADES[[#This Row],[Total Tarefas '[=']]],"CONCLUÍDA",IF(_xlpm.totItensNaoIniciados=TB_ATIVIDADES[[#This Row],[Total Tarefas '[=']]],IF(AND(DATE(YEAR(NOW()),MONTH(NOW()),DAY(NOW())) > IFERROR(DATE(YEAR(TB_ATIVIDADES[[#This Row],[Previsão Início '[=']]]),MONTH(TB_ATIVIDADES[[#This Row],[Previsão Início '[=']]]),DAY(TB_ATIVIDADES[[#This Row],[Previsão Início '[=']]])),FALSE)),"INÍCIO COM ATRASO","NÃO INICIADA"),IF(AND(DATE(YEAR(NOW()),MONTH(NOW()),DAY(NOW())) > IFERROR(DATE(YEAR(TB_ATIVIDADES[[#This Row],[Previsão Conclusão '[=']]]),MONTH(TB_ATIVIDADES[[#This Row],[Previsão Conclusão '[=']]]),DAY(TB_ATIVIDADES[[#This Row],[Previsão Conclusão '[=']]])),FALSE)),"CONCLUSÃO COM ATRASO","EM ANDAMENTO")))))) -> INÍCIO COM ATRASO
C13: =IF(TB_FASES[[#This Row],[Fase '[*']]]="","-",COUNTIF(TB_ATIVIDADES[Fase '[*']],TB_FASES[[#This Row],[Fase '[*']]])) -> - | D13: =IF(TB_FASES[[#This Row],[Fase '[*']]]="","-",SUMIF(TB_ATIVIDADES[Fase '[*']],TB_FASES[[#This Row],[Fase '[*']]],TB_ATIVIDADES[Total Tarefas '[=']])) -> - | E13: =IF(TB_FASES[[#This Row],[Fase '[*']]]="","-",_xlfn.LET(_xlpm.tot,COUNTIFS(TB_ATIVIDADES[Fase '[*']],TB_FASES[[#This Row],[Fase '[*']]],TB_ATIVIDADES[Status '[=']],"<>" & "CONCLUÍDA"),_xlpm.tot & IF(TB_FASES[[#This Row],[Total Atividades '[=']]]=0,""," (" & TEXT(_xlpm.tot/TB_FASES[[#This Row],[Total Atividades '[=']]],"0,0%") & ")"))) -> - | F13: =IF(TB_FASES[[#This Row],[Fase '[*']]]="","-",SUMIF(TB_ATIVIDADES[Fase '[*']],TB_FASES[[#This Row],[Fase '[*']]],TB_ATIVIDADES[Esforço Total (min) '[=']])) -> - | G13: =IF(TB_FASES[[#This Row],[Fase '[*']]]="","-",_xlfn.LET(_xlpm.esforcoRealizado,SUMIFS(TB_TAREFAS[Previsão Esforço (min) '[*']],TB_TAREFAS[Fase '[=']],TB_FASES[[#This Row],[Fase '[*']]],TB_TAREFAS[Situação da Execução '[*']],"CONCLUÍDA"),(TB_FASES[[#This Row],[Esforço Total (min) '[=']]]-_xlpm.esforcoRealizado) & IF(TB_FASES[[#This Row],[Esforço Total (min) '[=']]]>0," ("&TEXT((TB_FASES[[#This Row],[Esforço Total (min) '[=']]]-_xlpm.esforcoRealizado)/TB_FASES[[#This Row],[Esforço Total (min) '[=']]],"0,0%")&")",""))) -> - | H13: =IF(TB_FASES[[#This Row],[Fase '[*']]]="","-",_xlfn.LET(_xlpm.dataMin,_xlfn.MINIFS(TB_ATIVIDADES[Previsão Início '[=']],TB_ATIVIDADES[Fase '[*']],TB_FASES[[#This Row],[Fase '[*']]]),IF(_xlpm.dataMin=DATE(1900,1,0),"Indefinida",_xlpm.dataMin))) -> - | I13: =IF(TB_FASES[[#This Row],[Fase '[*']]]="","-",_xlfn.LET(_xlpm.dataMax,_xlfn.MAXIFS(TB_ATIVIDADES[Previsão Conclusão '[=']],TB_ATIVIDADES[Fase '[*']],TB_FASES[[#This Row],[Fase '[*']]]),IF(_xlpm.dataMax=DATE(1900,1,0),"Indefinida",_xlpm.dataMax))) -> - | J13: =IF(TB_FASES[[#This Row],[Fase '[*']]]="","-",IF(TB_FASES[[#This Row],[Total Atividades '[=']]]=0,"-",_xlfn.LET(_xlpm.totAtivNaoConcluidas,COUNTIFS(TB_ATIVIDADES[Fase '[*']],TB_FASES[[#This Row],[Fase '[*']]],TB_ATIVIDADES[Status '[=']],"<>" & "CONCLUÍDA"),_xlpm.totAtivConcluidas,TB_FASES[[#This Row],[Total Atividades '[=']]]-_xlpm.totAtivNaoConcluidas,_xlpm.totAtivNaoIniciadas,COUNTIFS(TB_ATIVIDADES[Fase '[*']],TB_FASES[[#This Row],[Fase '[*']]],TB_ATIVIDADES[Status '[=']],"NÃO INICIADA")+COUNTIFS(TB_ATIVIDADES[Fase '[*']],TB_FASES[[#This Row],[Fase '[*']]],TB_ATIVIDADES[Status '[=']],"INÍCIO COM ATRASO"),IF(_xlpm.totAtivConcluidas=TB_FASES[[#This Row],[Total Atividades '[=']]],"CONCLUÍDA",IF(_xlpm.totAtivNaoIniciadas=TB_FASES[[#This Row],[Total Atividades '[=']]],IF(AND(DATE(YEAR(NOW()),MONTH(NOW()),DAY(NOW())) > IFERROR(DATE(YEAR(TB_FASES[[#This Row],[Previsão Início '[=']]]),MONTH(TB_FASES[[#This Row],[Previsão Início '[=']]]),DAY(TB_FASES[[#This Row],[Previsão Início '[=']]])),FALSE)),"INICIO COM ATRASO","NÃO INICIADA"),IF(AND(DATE(YEAR(NOW()),MONTH(NOW()),DAY(NOW())) > IFERROR(DATE(YEAR(TB_FASES[[#This Row],[Previsão Conclusão '[=']]]),MONTH(TB_FASES[[#This Row],[Previsão Conclusão '[=']]]),DAY(TB_FASES[[#This Row],[Previsão Conclusão '[=']]])),FALSE)),"CONCLUSÃO COM ATRASO","EM ANDAMENTO")))))) -> - | L13: Desenv. Mdl. Criar Bolão | M13: F1-DESENV | N13: =IF(OR(TB_ATIVIDADES[[#This Row],[Atividade '[*']]]="",TB_ATIVIDADES[[#This Row],[Fase '[*']]]=""),"-",COUNTIF(TB_TAREFAS[Atividade '[*']],TB_ATIVIDADES[[#This Row],[Atividade '[*']]])) -> 5 | O13: =IF(OR(TB_ATIVIDADES[[#This Row],[Atividade '[*']]]="",TB_ATIVIDADES[[#This Row],[Fase '[*']]]=""),"-",_xlfn.LET(_xlpm.tot,COUNTIFS(TB_TAREFAS[Atividade '[*']],TB_ATIVIDADES[[#This Row],[Atividade '[*']]],TB_TAREFAS[Situação da Execução '[*']],"<>" & "CONCLUÍDA",TB_TAREFAS[Situação da Execução '[*']],"<>"&"DESNECESSÁRIA"),_xlpm.tot & IF(TB_ATIVIDADES[[#This Row],[Total Tarefas '[=']]]=0,""," (" & TEXT(_xlpm.tot/TB_ATIVIDADES[[#This Row],[Total Tarefas '[=']]],"0,0%") & ")"))) -> 5 (100,0%) | P13: =IF(OR(TB_ATIVIDADES[[#This Row],[Atividade '[*']]]="",TB_ATIVIDADES[[#This Row],[Fase '[*']]]=""),"-",SUMIF(TB_TAREFAS[Atividade '[*']],TB_ATIVIDADES[[#This Row],[Atividade '[*']]],TB_TAREFAS[Previsão Esforço (min) '[*']])) -> 95 | Q13: =IF(OR(TB_ATIVIDADES[[#This Row],[Atividade '[*']]]="",TB_ATIVIDADES[[#This Row],[Fase '[*']]]=""),"-",_xlfn.LET(_xlpm.esforçoRealizado,SUMIFS(TB_TAREFAS[Previsão Esforço (min) '[*']],TB_TAREFAS[Atividade '[*']],TB_ATIVIDADES[[#This Row],[Atividade '[*']]],TB_TAREFAS[Situação da Execução '[*']],"CONCLUÍDA")+SUMIFS(TB_TAREFAS[Previsão Esforço (min) '[*']],TB_TAREFAS[Atividade '[*']],TB_ATIVIDADES[[#This Row],[Atividade '[*']]],TB_TAREFAS[Situação da Execução '[*']],"DESNECESSÁRIA"),TB_ATIVIDADES[[#This Row],[Esforço Total (min) '[=']]]-_xlpm.esforçoRealizado & IF(TB_ATIVIDADES[[#This Row],[Esforço Total (min) '[=']]]=0,""," (" & TEXT((TB_ATIVIDADES[[#This Row],[Esforço Total (min) '[=']]]-_xlpm.esforçoRealizado) / TB_ATIVIDADES[[#This Row],[Esforço Total (min) '[=']]],"0,0%") & ")"))) -> 95 (100,0%) | R13: =IF(OR(TB_ATIVIDADES[[#This Row],[Atividade '[*']]]="",TB_ATIVIDADES[[#This Row],[Fase '[*']]]=""),"-",_xlfn.LET(_xlpm.dataMin,_xlfn.MINIFS(TB_TAREFAS[Previsão Início '[*']],TB_TAREFAS[Atividade '[*']],TB_ATIVIDADES[[#This Row],[Atividade '[*']]]),IF(_xlpm.dataMin=0,"-",_xlpm.dataMin))) -> 46085 | S13: =IF(OR(TB_ATIVIDADES[[#This Row],[Atividade '[*']]]="",TB_ATIVIDADES[[#This Row],[Fase '[*']]]=""),"-",_xlfn.LET(_xlpm.dataMax,_xlfn.MAXIFS(TB_TAREFAS[Previsão Conclusão '[*']],TB_TAREFAS[Atividade '[*']],TB_ATIVIDADES[[#This Row],[Atividade '[*']]]),IF(_xlpm.dataMax=0,"-",_xlpm.dataMax))) -> 46085 | T13: =IF(OR(TB_ATIVIDADES[[#This Row],[Atividade '[*']]]="",TB_ATIVIDADES[[#This Row],[Fase '[*']]]=""),"-",IF(TB_ATIVIDADES[[#This Row],[Total Tarefas '[=']]]=0,"-",_xlfn.LET(_xlpm.totItensNaoConcluidos,COUNTIFS(TB_TAREFAS[Atividade '[*']],TB_ATIVIDADES[[#This Row],[Atividade '[*']]],TB_TAREFAS[Situação da Execução '[*']],"<>" & "CONCLUÍDA",TB_TAREFAS[Situação da Execução '[*']],"<>" & "DESNECESSÁRIA"),_xlpm.totItensConcluidos,TB_ATIVIDADES[[#This Row],[Total Tarefas '[=']]]-_xlpm.totItensNaoConcluidos,_xlpm.totItensNaoIniciados,COUNTIFS(TB_TAREFAS[Atividade '[*']],TB_ATIVIDADES[[#This Row],[Atividade '[*']]],TB_TAREFAS[Situação da Execução '[*']],"NÃO INICIADA"),IF(_xlpm.totItensConcluidos=TB_ATIVIDADES[[#This Row],[Total Tarefas '[=']]],"CONCLUÍDA",IF(_xlpm.totItensNaoIniciados=TB_ATIVIDADES[[#This Row],[Total Tarefas '[=']]],IF(AND(DATE(YEAR(NOW()),MONTH(NOW()),DAY(NOW())) > IFERROR(DATE(YEAR(TB_ATIVIDADES[[#This Row],[Previsão Início '[=']]]),MONTH(TB_ATIVIDADES[[#This Row],[Previsão Início '[=']]]),DAY(TB_ATIVIDADES[[#This Row],[Previsão Início '[=']]])),FALSE)),"INÍCIO COM ATRASO","NÃO INICIADA"),IF(AND(DATE(YEAR(NOW()),MONTH(NOW()),DAY(NOW())) > IFERROR(DATE(YEAR(TB_ATIVIDADES[[#This Row],[Previsão Conclusão '[=']]]),MONTH(TB_ATIVIDADES[[#This Row],[Previsão Conclusão '[=']]]),DAY(TB_ATIVIDADES[[#This Row],[Previsão Conclusão '[=']]])),FALSE)),"CONCLUSÃO COM ATRASO","EM ANDAMENTO")))))) -> INÍCIO COM ATRASO
C14: =IF(TB_FASES[[#This Row],[Fase '[*']]]="","-",COUNTIF(TB_ATIVIDADES[Fase '[*']],TB_FASES[[#This Row],[Fase '[*']]])) -> - | D14: =IF(TB_FASES[[#This Row],[Fase '[*']]]="","-",SUMIF(TB_ATIVIDADES[Fase '[*']],TB_FASES[[#This Row],[Fase '[*']]],TB_ATIVIDADES[Total Tarefas '[=']])) -> - | E14: =IF(TB_FASES[[#This Row],[Fase '[*']]]="","-",_xlfn.LET(_xlpm.tot,COUNTIFS(TB_ATIVIDADES[Fase '[*']],TB_FASES[[#This Row],[Fase '[*']]],TB_ATIVIDADES[Status '[=']],"<>" & "CONCLUÍDA"),_xlpm.tot & IF(TB_FASES[[#This Row],[Total Atividades '[=']]]=0,""," (" & TEXT(_xlpm.tot/TB_FASES[[#This Row],[Total Atividades '[=']]],"0,0%") & ")"))) -> - | F14: =IF(TB_FASES[[#This Row],[Fase '[*']]]="","-",SUMIF(TB_ATIVIDADES[Fase '[*']],TB_FASES[[#This Row],[Fase '[*']]],TB_ATIVIDADES[Esforço Total (min) '[=']])) -> - | G14: =IF(TB_FASES[[#This Row],[Fase '[*']]]="","-",_xlfn.LET(_xlpm.esforcoRealizado,SUMIFS(TB_TAREFAS[Previsão Esforço (min) '[*']],TB_TAREFAS[Fase '[=']],TB_FASES[[#This Row],[Fase '[*']]],TB_TAREFAS[Situação da Execução '[*']],"CONCLUÍDA"),(TB_FASES[[#This Row],[Esforço Total (min) '[=']]]-_xlpm.esforcoRealizado) & IF(TB_FASES[[#This Row],[Esforço Total (min) '[=']]]>0," ("&TEXT((TB_FASES[[#This Row],[Esforço Total (min) '[=']]]-_xlpm.esforcoRealizado)/TB_FASES[[#This Row],[Esforço Total (min) '[=']]],"0,0%")&")",""))) -> - | H14: =IF(TB_FASES[[#This Row],[Fase '[*']]]="","-",_xlfn.LET(_xlpm.dataMin,_xlfn.MINIFS(TB_ATIVIDADES[Previsão Início '[=']],TB_ATIVIDADES[Fase '[*']],TB_FASES[[#This Row],[Fase '[*']]]),IF(_xlpm.dataMin=DATE(1900,1,0),"Indefinida",_xlpm.dataMin))) -> - | I14: =IF(TB_FASES[[#This Row],[Fase '[*']]]="","-",_xlfn.LET(_xlpm.dataMax,_xlfn.MAXIFS(TB_ATIVIDADES[Previsão Conclusão '[=']],TB_ATIVIDADES[Fase '[*']],TB_FASES[[#This Row],[Fase '[*']]]),IF(_xlpm.dataMax=DATE(1900,1,0),"Indefinida",_xlpm.dataMax))) -> - | J14: =IF(TB_FASES[[#This Row],[Fase '[*']]]="","-",IF(TB_FASES[[#This Row],[Total Atividades '[=']]]=0,"-",_xlfn.LET(_xlpm.totAtivNaoConcluidas,COUNTIFS(TB_ATIVIDADES[Fase '[*']],TB_FASES[[#This Row],[Fase '[*']]],TB_ATIVIDADES[Status '[=']],"<>" & "CONCLUÍDA"),_xlpm.totAtivConcluidas,TB_FASES[[#This Row],[Total Atividades '[=']]]-_xlpm.totAtivNaoConcluidas,_xlpm.totAtivNaoIniciadas,COUNTIFS(TB_ATIVIDADES[Fase '[*']],TB_FASES[[#This Row],[Fase '[*']]],TB_ATIVIDADES[Status '[=']],"NÃO INICIADA")+COUNTIFS(TB_ATIVIDADES[Fase '[*']],TB_FASES[[#This Row],[Fase '[*']]],TB_ATIVIDADES[Status '[=']],"INÍCIO COM ATRASO"),IF(_xlpm.totAtivConcluidas=TB_FASES[[#This Row],[Total Atividades '[=']]],"CONCLUÍDA",IF(_xlpm.totAtivNaoIniciadas=TB_FASES[[#This Row],[Total Atividades '[=']]],IF(AND(DATE(YEAR(NOW()),MONTH(NOW()),DAY(NOW())) > IFERROR(DATE(YEAR(TB_FASES[[#This Row],[Previsão Início '[=']]]),MONTH(TB_FASES[[#This Row],[Previsão Início '[=']]]),DAY(TB_FASES[[#This Row],[Previsão Início '[=']]])),FALSE)),"INICIO COM ATRASO","NÃO INICIADA"),IF(AND(DATE(YEAR(NOW()),MONTH(NOW()),DAY(NOW())) > IFERROR(DATE(YEAR(TB_FASES[[#This Row],[Previsão Conclusão '[=']]]),MONTH(TB_FASES[[#This Row],[Previsão Conclusão '[=']]]),DAY(TB_FASES[[#This Row],[Previsão Conclusão '[=']]])),FALSE)),"CONCLUSÃO COM ATRASO","EM ANDAMENTO")))))) -> - | L14: Desenv. Mdl. Entrar Bolão | M14: F1-DESENV | N14: =IF(OR(TB_ATIVIDADES[[#This Row],[Atividade '[*']]]="",TB_ATIVIDADES[[#This Row],[Fase '[*']]]=""),"-",COUNTIF(TB_TAREFAS[Atividade '[*']],TB_ATIVIDADES[[#This Row],[Atividade '[*']]])) -> 5 | O14: =IF(OR(TB_ATIVIDADES[[#This Row],[Atividade '[*']]]="",TB_ATIVIDADES[[#This Row],[Fase '[*']]]=""),"-",_xlfn.LET(_xlpm.tot,COUNTIFS(TB_TAREFAS[Atividade '[*']],TB_ATIVIDADES[[#This Row],[Atividade '[*']]],TB_TAREFAS[Situação da Execução '[*']],"<>" & "CONCLUÍDA",TB_TAREFAS[Situação da Execução '[*']],"<>"&"DESNECESSÁRIA"),_xlpm.tot & IF(TB_ATIVIDADES[[#This Row],[Total Tarefas '[=']]]=0,""," (" & TEXT(_xlpm.tot/TB_ATIVIDADES[[#This Row],[Total Tarefas '[=']]],"0,0%") & ")"))) -> 5 (100,0%) | P14: =IF(OR(TB_ATIVIDADES[[#This Row],[Atividade '[*']]]="",TB_ATIVIDADES[[#This Row],[Fase '[*']]]=""),"-",SUMIF(TB_TAREFAS[Atividade '[*']],TB_ATIVIDADES[[#This Row],[Atividade '[*']]],TB_TAREFAS[Previsão Esforço (min) '[*']])) -> 95 | Q14: =IF(OR(TB_ATIVIDADES[[#This Row],[Atividade '[*']]]="",TB_ATIVIDADES[[#This Row],[Fase '[*']]]=""),"-",_xlfn.LET(_xlpm.esforçoRealizado,SUMIFS(TB_TAREFAS[Previsão Esforço (min) '[*']],TB_TAREFAS[Atividade '[*']],TB_ATIVIDADES[[#This Row],[Atividade '[*']]],TB_TAREFAS[Situação da Execução '[*']],"CONCLUÍDA")+SUMIFS(TB_TAREFAS[Previsão Esforço (min) '[*']],TB_TAREFAS[Atividade '[*']],TB_ATIVIDADES[[#This Row],[Atividade '[*']]],TB_TAREFAS[Situação da Execução '[*']],"DESNECESSÁRIA"),TB_ATIVIDADES[[#This Row],[Esforço Total (min) '[=']]]-_xlpm.esforçoRealizado & IF(TB_ATIVIDADES[[#This Row],[Esforço Total (min) '[=']]]=0,""," (" & TEXT((TB_ATIVIDADES[[#This Row],[Esforço Total (min) '[=']]]-_xlpm.esforçoRealizado) / TB_ATIVIDADES[[#This Row],[Esforço Total (min) '[=']]],"0,0%") & ")"))) -> 95 (100,0%) | R14: =IF(OR(TB_ATIVIDADES[[#This Row],[Atividade '[*']]]="",TB_ATIVIDADES[[#This Row],[Fase '[*']]]=""),"-",_xlfn.LET(_xlpm.dataMin,_xlfn.MINIFS(TB_TAREFAS[Previsão Início '[*']],TB_TAREFAS[Atividade '[*']],TB_ATIVIDADES[[#This Row],[Atividade '[*']]]),IF(_xlpm.dataMin=0,"-",_xlpm.dataMin))) -> 46085 | S14: =IF(OR(TB_ATIVIDADES[[#This Row],[Atividade '[*']]]="",TB_ATIVIDADES[[#This Row],[Fase '[*']]]=""),"-",_xlfn.LET(_xlpm.dataMax,_xlfn.MAXIFS(TB_TAREFAS[Previsão Conclusão '[*']],TB_TAREFAS[Atividade '[*']],TB_ATIVIDADES[[#This Row],[Atividade '[*']]]),IF(_xlpm.dataMax=0,"-",_xlpm.dataMax))) -> 46085 | T14: =IF(OR(TB_ATIVIDADES[[#This Row],[Atividade '[*']]]="",TB_ATIVIDADES[[#This Row],[Fase '[*']]]=""),"-",IF(TB_ATIVIDADES[[#This Row],[Total Tarefas '[=']]]=0,"-",_xlfn.LET(_xlpm.totItensNaoConcluidos,COUNTIFS(TB_TAREFAS[Atividade '[*']],TB_ATIVIDADES[[#This Row],[Atividade '[*']]],TB_TAREFAS[Situação da Execução '[*']],"<>" & "CONCLUÍDA",TB_TAREFAS[Situação da Execução '[*']],"<>" & "DESNECESSÁRIA"),_xlpm.totItensConcluidos,TB_ATIVIDADES[[#This Row],[Total Tarefas '[=']]]-_xlpm.totItensNaoConcluidos,_xlpm.totItensNaoIniciados,COUNTIFS(TB_TAREFAS[Atividade '[*']],TB_ATIVIDADES[[#This Row],[Atividade '[*']]],TB_TAREFAS[Situação da Execução '[*']],"NÃO INICIADA"),IF(_xlpm.totItensConcluidos=TB_ATIVIDADES[[#This Row],[Total Tarefas '[=']]],"CONCLUÍDA",IF(_xlpm.totItensNaoIniciados=TB_ATIVIDADES[[#This Row],[Total Tarefas '[=']]],IF(AND(DATE(YEAR(NOW()),MONTH(NOW()),DAY(NOW())) > IFERROR(DATE(YEAR(TB_ATIVIDADES[[#This Row],[Previsão Início '[=']]]),MONTH(TB_ATIVIDADES[[#This Row],[Previsão Início '[=']]]),DAY(TB_ATIVIDADES[[#This Row],[Previsão Início '[=']]])),FALSE)),"INÍCIO COM ATRASO","NÃO INICIADA"),IF(AND(DATE(YEAR(NOW()),MONTH(NOW()),DAY(NOW())) > IFERROR(DATE(YEAR(TB_ATIVIDADES[[#This Row],[Previsão Conclusão '[=']]]),MONTH(TB_ATIVIDADES[[#This Row],[Previsão Conclusão '[=']]]),DAY(TB_ATIVIDADES[[#This Row],[Previsão Conclusão '[=']]])),FALSE)),"CONCLUSÃO COM ATRASO","EM ANDAMENTO")))))) -> INÍCIO COM ATRASO
C15: =IF(TB_FASES[[#This Row],[Fase '[*']]]="","-",COUNTIF(TB_ATIVIDADES[Fase '[*']],TB_FASES[[#This Row],[Fase '[*']]])) -> - | D15: =IF(TB_FASES[[#This Row],[Fase '[*']]]="","-",SUMIF(TB_ATIVIDADES[Fase '[*']],TB_FASES[[#This Row],[Fase '[*']]],TB_ATIVIDADES[Total Tarefas '[=']])) -> - | E15: =IF(TB_FASES[[#This Row],[Fase '[*']]]="","-",_xlfn.LET(_xlpm.tot,COUNTIFS(TB_ATIVIDADES[Fase '[*']],TB_FASES[[#This Row],[Fase '[*']]],TB_ATIVIDADES[Status '[=']],"<>" & "CONCLUÍDA"),_xlpm.tot & IF(TB_FASES[[#This Row],[Total Atividades '[=']]]=0,""," (" & TEXT(_xlpm.tot/TB_FASES[[#This Row],[Total Atividades '[=']]],"0,0%") & ")"))) -> - | F15: =IF(TB_FASES[[#This Row],[Fase '[*']]]="","-",SUMIF(TB_ATIVIDADES[Fase '[*']],TB_FASES[[#This Row],[Fase '[*']]],TB_ATIVIDADES[Esforço Total (min) '[=']])) -> - | G15: =IF(TB_FASES[[#This Row],[Fase '[*']]]="","-",_xlfn.LET(_xlpm.esforcoRealizado,SUMIFS(TB_TAREFAS[Previsão Esforço (min) '[*']],TB_TAREFAS[Fase '[=']],TB_FASES[[#This Row],[Fase '[*']]],TB_TAREFAS[Situação da Execução '[*']],"CONCLUÍDA"),(TB_FASES[[#This Row],[Esforço Total (min) '[=']]]-_xlpm.esforcoRealizado) & IF(TB_FASES[[#This Row],[Esforço Total (min) '[=']]]>0," ("&TEXT((TB_FASES[[#This Row],[Esforço Total (min) '[=']]]-_xlpm.esforcoRealizado)/TB_FASES[[#This Row],[Esforço Total (min) '[=']]],"0,0%")&")",""))) -> - | H15: =IF(TB_FASES[[#This Row],[Fase '[*']]]="","-",_xlfn.LET(_xlpm.dataMin,_xlfn.MINIFS(TB_ATIVIDADES[Previsão Início '[=']],TB_ATIVIDADES[Fase '[*']],TB_FASES[[#This Row],[Fase '[*']]]),IF(_xlpm.dataMin=DATE(1900,1,0),"Indefinida",_xlpm.dataMin))) -> - | I15: =IF(TB_FASES[[#This Row],[Fase '[*']]]="","-",_xlfn.LET(_xlpm.dataMax,_xlfn.MAXIFS(TB_ATIVIDADES[Previsão Conclusão '[=']],TB_ATIVIDADES[Fase '[*']],TB_FASES[[#This Row],[Fase '[*']]]),IF(_xlpm.dataMax=DATE(1900,1,0),"Indefinida",_xlpm.dataMax))) -> - | J15: =IF(TB_FASES[[#This Row],[Fase '[*']]]="","-",IF(TB_FASES[[#This Row],[Total Atividades '[=']]]=0,"-",_xlfn.LET(_xlpm.totAtivNaoConcluidas,COUNTIFS(TB_ATIVIDADES[Fase '[*']],TB_FASES[[#This Row],[Fase '[*']]],TB_ATIVIDADES[Status '[=']],"<>" & "CONCLUÍDA"),_xlpm.totAtivConcluidas,TB_FASES[[#This Row],[Total Atividades '[=']]]-_xlpm.totAtivNaoConcluidas,_xlpm.totAtivNaoIniciadas,COUNTIFS(TB_ATIVIDADES[Fase '[*']],TB_FASES[[#This Row],[Fase '[*']]],TB_ATIVIDADES[Status '[=']],"NÃO INICIADA")+COUNTIFS(TB_ATIVIDADES[Fase '[*']],TB_FASES[[#This Row],[Fase '[*']]],TB_ATIVIDADES[Status '[=']],"INÍCIO COM ATRASO"),IF(_xlpm.totAtivConcluidas=TB_FASES[[#This Row],[Total Atividades '[=']]],"CONCLUÍDA",IF(_xlpm.totAtivNaoIniciadas=TB_FASES[[#This Row],[Total Atividades '[=']]],IF(AND(DATE(YEAR(NOW()),MONTH(NOW()),DAY(NOW())) > IFERROR(DATE(YEAR(TB_FASES[[#This Row],[Previsão Início '[=']]]),MONTH(TB_FASES[[#This Row],[Previsão Início '[=']]]),DAY(TB_FASES[[#This Row],[Previsão Início '[=']]])),FALSE)),"INICIO COM ATRASO","NÃO INICIADA"),IF(AND(DATE(YEAR(NOW()),MONTH(NOW()),DAY(NOW())) > IFERROR(DATE(YEAR(TB_FASES[[#This Row],[Previsão Conclusão '[=']]]),MONTH(TB_FASES[[#This Row],[Previsão Conclusão '[=']]]),DAY(TB_FASES[[#This Row],[Previsão Conclusão '[=']]])),FALSE)),"CONCLUSÃO COM ATRASO","EM ANDAMENTO")))))) -> - | L15: Desenv. Pg. Bolão | M15: F1-DESENV | N15: =IF(OR(TB_ATIVIDADES[[#This Row],[Atividade '[*']]]="",TB_ATIVIDADES[[#This Row],[Fase '[*']]]=""),"-",COUNTIF(TB_TAREFAS[Atividade '[*']],TB_ATIVIDADES[[#This Row],[Atividade '[*']]])) -> 9 | O15: =IF(OR(TB_ATIVIDADES[[#This Row],[Atividade '[*']]]="",TB_ATIVIDADES[[#This Row],[Fase '[*']]]=""),"-",_xlfn.LET(_xlpm.tot,COUNTIFS(TB_TAREFAS[Atividade '[*']],TB_ATIVIDADES[[#This Row],[Atividade '[*']]],TB_TAREFAS[Situação da Execução '[*']],"<>" & "CONCLUÍDA",TB_TAREFAS[Situação da Execução '[*']],"<>"&"DESNECESSÁRIA"),_xlpm.tot & IF(TB_ATIVIDADES[[#This Row],[Total Tarefas '[=']]]=0,""," (" & TEXT(_xlpm.tot/TB_ATIVIDADES[[#This Row],[Total Tarefas '[=']]],"0,0%") & ")"))) -> 9 (100,0%) | P15: =IF(OR(TB_ATIVIDADES[[#This Row],[Atividade '[*']]]="",TB_ATIVIDADES[[#This Row],[Fase '[*']]]=""),"-",SUMIF(TB_TAREFAS[Atividade '[*']],TB_ATIVIDADES[[#This Row],[Atividade '[*']]],TB_TAREFAS[Previsão Esforço (min) '[*']])) -> 205 | Q15: =IF(OR(TB_ATIVIDADES[[#This Row],[Atividade '[*']]]="",TB_ATIVIDADES[[#This Row],[Fase '[*']]]=""),"-",_xlfn.LET(_xlpm.esforçoRealizado,SUMIFS(TB_TAREFAS[Previsão Esforço (min) '[*']],TB_TAREFAS[Atividade '[*']],TB_ATIVIDADES[[#This Row],[Atividade '[*']]],TB_TAREFAS[Situação da Execução '[*']],"CONCLUÍDA")+SUMIFS(TB_TAREFAS[Previsão Esforço (min) '[*']],TB_TAREFAS[Atividade '[*']],TB_ATIVIDADES[[#This Row],[Atividade '[*']]],TB_TAREFAS[Situação da Execução '[*']],"DESNECESSÁRIA"),TB_ATIVIDADES[[#This Row],[Esforço Total (min) '[=']]]-_xlpm.esforçoRealizado & IF(TB_ATIVIDADES[[#This Row],[Esforço Total (min) '[=']]]=0,""," (" & TEXT((TB_ATIVIDADES[[#This Row],[Esforço Total (min) '[=']]]-_xlpm.esforçoRealizado) / TB_ATIVIDADES[[#This Row],[Esforço Total (min) '[=']]],"0,0%") & ")"))) -> 205 (100,0%) | R15: =IF(OR(TB_ATIVIDADES[[#This Row],[Atividade '[*']]]="",TB_ATIVIDADES[[#This Row],[Fase '[*']]]=""),"-",_xlfn.LET(_xlpm.dataMin,_xlfn.MINIFS(TB_TAREFAS[Previsão Início '[*']],TB_TAREFAS[Atividade '[*']],TB_ATIVIDADES[[#This Row],[Atividade '[*']]]),IF(_xlpm.dataMin=0,"-",_xlpm.dataMin))) -> 46086 | S15: =IF(OR(TB_ATIVIDADES[[#This Row],[Atividade '[*']]]="",TB_ATIVIDADES[[#This Row],[Fase '[*']]]=""),"-",_xlfn.LET(_xlpm.dataMax,_xlfn.MAXIFS(TB_TAREFAS[Previsão Conclusão '[*']],TB_TAREFAS[Atividade '[*']],TB_ATIVIDADES[[#This Row],[Atividade '[*']]]),IF(_xlpm.dataMax=0,"-",_xlpm.dataMax))) -> 46091 | T15: =IF(OR(TB_ATIVIDADES[[#This Row],[Atividade '[*']]]="",TB_ATIVIDADES[[#This Row],[Fase '[*']]]=""),"-",IF(TB_ATIVIDADES[[#This Row],[Total Tarefas '[=']]]=0,"-",_xlfn.LET(_xlpm.totItensNaoConcluidos,COUNTIFS(TB_TAREFAS[Atividade '[*']],TB_ATIVIDADES[[#This Row],[Atividade '[*']]],TB_TAREFAS[Situação da Execução '[*']],"<>" & "CONCLUÍDA",TB_TAREFAS[Situação da Execução '[*']],"<>" & "DESNECESSÁRIA"),_xlpm.totItensConcluidos,TB_ATIVIDADES[[#This Row],[Total Tarefas '[=']]]-_xlpm.totItensNaoConcluidos,_xlpm.totItensNaoIniciados,COUNTIFS(TB_TAREFAS[Atividade '[*']],TB_ATIVIDADES[[#This Row],[Atividade '[*']]],TB_TAREFAS[Situação da Execução '[*']],"NÃO INICIADA"),IF(_xlpm.totItensConcluidos=TB_ATIVIDADES[[#This Row],[Total Tarefas '[=']]],"CONCLUÍDA",IF(_xlpm.totItensNaoIniciados=TB_ATIVIDADES[[#This Row],[Total Tarefas '[=']]],IF(AND(DATE(YEAR(NOW()),MONTH(NOW()),DAY(NOW())) > IFERROR(DATE(YEAR(TB_ATIVIDADES[[#This Row],[Previsão Início '[=']]]),MONTH(TB_ATIVIDADES[[#This Row],[Previsão Início '[=']]]),DAY(TB_ATIVIDADES[[#This Row],[Previsão Início '[=']]])),FALSE)),"INÍCIO COM ATRASO","NÃO INICIADA"),IF(AND(DATE(YEAR(NOW()),MONTH(NOW()),DAY(NOW())) > IFERROR(DATE(YEAR(TB_ATIVIDADES[[#This Row],[Previsão Conclusão '[=']]]),MONTH(TB_ATIVIDADES[[#This Row],[Previsão Conclusão '[=']]]),DAY(TB_ATIVIDADES[[#This Row],[Previsão Conclusão '[=']]])),FALSE)),"CONCLUSÃO COM ATRASO","EM ANDAMENTO")))))) -> INÍCIO COM ATRASO
C16: =IF(TB_FASES[[#This Row],[Fase '[*']]]="","-",COUNTIF(TB_ATIVIDADES[Fase '[*']],TB_FASES[[#This Row],[Fase '[*']]])) -> - | D16: =IF(TB_FASES[[#This Row],[Fase '[*']]]="","-",SUMIF(TB_ATIVIDADES[Fase '[*']],TB_FASES[[#This Row],[Fase '[*']]],TB_ATIVIDADES[Total Tarefas '[=']])) -> - | E16: =IF(TB_FASES[[#This Row],[Fase '[*']]]="","-",_xlfn.LET(_xlpm.tot,COUNTIFS(TB_ATIVIDADES[Fase '[*']],TB_FASES[[#This Row],[Fase '[*']]],TB_ATIVIDADES[Status '[=']],"<>" & "CONCLUÍDA"),_xlpm.tot & IF(TB_FASES[[#This Row],[Total Atividades '[=']]]=0,""," (" & TEXT(_xlpm.tot/TB_FASES[[#This Row],[Total Atividades '[=']]],"0,0%") & ")"))) -> - | F16: =IF(TB_FASES[[#This Row],[Fase '[*']]]="","-",SUMIF(TB_ATIVIDADES[Fase '[*']],TB_FASES[[#This Row],[Fase '[*']]],TB_ATIVIDADES[Esforço Total (min) '[=']])) -> - | G16: =IF(TB_FASES[[#This Row],[Fase '[*']]]="","-",_xlfn.LET(_xlpm.esforcoRealizado,SUMIFS(TB_TAREFAS[Previsão Esforço (min) '[*']],TB_TAREFAS[Fase '[=']],TB_FASES[[#This Row],[Fase '[*']]],TB_TAREFAS[Situação da Execução '[*']],"CONCLUÍDA"),(TB_FASES[[#This Row],[Esforço Total (min) '[=']]]-_xlpm.esforcoRealizado) & IF(TB_FASES[[#This Row],[Esforço Total (min) '[=']]]>0," ("&TEXT((TB_FASES[[#This Row],[Esforço Total (min) '[=']]]-_xlpm.esforcoRealizado)/TB_FASES[[#This Row],[Esforço Total (min) '[=']]],"0,0%")&")",""))) -> - | H16: =IF(TB_FASES[[#This Row],[Fase '[*']]]="","-",_xlfn.LET(_xlpm.dataMin,_xlfn.MINIFS(TB_ATIVIDADES[Previsão Início '[=']],TB_ATIVIDADES[Fase '[*']],TB_FASES[[#This Row],[Fase '[*']]]),IF(_xlpm.dataMin=DATE(1900,1,0),"Indefinida",_xlpm.dataMin))) -> - | I16: =IF(TB_FASES[[#This Row],[Fase '[*']]]="","-",_xlfn.LET(_xlpm.dataMax,_xlfn.MAXIFS(TB_ATIVIDADES[Previsão Conclusão '[=']],TB_ATIVIDADES[Fase '[*']],TB_FASES[[#This Row],[Fase '[*']]]),IF(_xlpm.dataMax=DATE(1900,1,0),"Indefinida",_xlpm.dataMax))) -> - | J16: =IF(TB_FASES[[#This Row],[Fase '[*']]]="","-",IF(TB_FASES[[#This Row],[Total Atividades '[=']]]=0,"-",_xlfn.LET(_xlpm.totAtivNaoConcluidas,COUNTIFS(TB_ATIVIDADES[Fase '[*']],TB_FASES[[#This Row],[Fase '[*']]],TB_ATIVIDADES[Status '[=']],"<>" & "CONCLUÍDA"),_xlpm.totAtivConcluidas,TB_FASES[[#This Row],[Total Atividades '[=']]]-_xlpm.totAtivNaoConcluidas,_xlpm.totAtivNaoIniciadas,COUNTIFS(TB_ATIVIDADES[Fase '[*']],TB_FASES[[#This Row],[Fase '[*']]],TB_ATIVIDADES[Status '[=']],"NÃO INICIADA")+COUNTIFS(TB_ATIVIDADES[Fase '[*']],TB_FASES[[#This Row],[Fase '[*']]],TB_ATIVIDADES[Status '[=']],"INÍCIO COM ATRASO"),IF(_xlpm.totAtivConcluidas=TB_FASES[[#This Row],[Total Atividades '[=']]],"CONCLUÍDA",IF(_xlpm.totAtivNaoIniciadas=TB_FASES[[#This Row],[Total Atividades '[=']]],IF(AND(DATE(YEAR(NOW()),MONTH(NOW()),DAY(NOW())) > IFERROR(DATE(YEAR(TB_FASES[[#This Row],[Previsão Início '[=']]]),MONTH(TB_FASES[[#This Row],[Previsão Início '[=']]]),DAY(TB_FASES[[#This Row],[Previsão Início '[=']]])),FALSE)),"INICIO COM ATRASO","NÃO INICIADA"),IF(AND(DATE(YEAR(NOW()),MONTH(NOW()),DAY(NOW())) > IFERROR(DATE(YEAR(TB_FASES[[#This Row],[Previsão Conclusão '[=']]]),MONTH(TB_FASES[[#This Row],[Previsão Conclusão '[=']]]),DAY(TB_FASES[[#This Row],[Previsão Conclusão '[=']]])),FALSE)),"CONCLUSÃO COM ATRASO","EM ANDAMENTO")))))) -> - | L16: Desenv. Mdl. Editar Bolão | M16: F1-DESENV | N16: =IF(OR(TB_ATIVIDADES[[#This Row],[Atividade '[*']]]="",TB_ATIVIDADES[[#This Row],[Fase '[*']]]=""),"-",COUNTIF(TB_TAREFAS[Atividade '[*']],TB_ATIVIDADES[[#This Row],[Atividade '[*']]])) -> 6 | O16: =IF(OR(TB_ATIVIDADES[[#This Row],[Atividade '[*']]]="",TB_ATIVIDADES[[#This Row],[Fase '[*']]]=""),"-",_xlfn.LET(_xlpm.tot,COUNTIFS(TB_TAREFAS[Atividade '[*']],TB_ATIVIDADES[[#This Row],[Atividade '[*']]],TB_TAREFAS[Situação da Execução '[*']],"<>" & "CONCLUÍDA",TB_TAREFAS[Situação da Execução '[*']],"<>"&"DESNECESSÁRIA"),_xlpm.tot & IF(TB_ATIVIDADES[[#This Row],[Total Tarefas '[=']]]=0,""," (" & TEXT(_xlpm.tot/TB_ATIVIDADES[[#This Row],[Total Tarefas '[=']]],"0,0%") & ")"))) -> 6 (100,0%) | P16: =IF(OR(TB_ATIVIDADES[[#This Row],[Atividade '[*']]]="",TB_ATIVIDADES[[#This Row],[Fase '[*']]]=""),"-",SUMIF(TB_TAREFAS[Atividade '[*']],TB_ATIVIDADES[[#This Row],[Atividade '[*']]],TB_TAREFAS[Previsão Esforço (min) '[*']])) -> 105 | Q16: =IF(OR(TB_ATIVIDADES[[#This Row],[Atividade '[*']]]="",TB_ATIVIDADES[[#This Row],[Fase '[*']]]=""),"-",_xlfn.LET(_xlpm.esforçoRealizado,SUMIFS(TB_TAREFAS[Previsão Esforço (min) '[*']],TB_TAREFAS[Atividade '[*']],TB_ATIVIDADES[[#This Row],[Atividade '[*']]],TB_TAREFAS[Situação da Execução '[*']],"CONCLUÍDA")+SUMIFS(TB_TAREFAS[Previsão Esforço (min) '[*']],TB_TAREFAS[Atividade '[*']],TB_ATIVIDADES[[#This Row],[Atividade '[*']]],TB_TAREFAS[Situação da Execução '[*']],"DESNECESSÁRIA"),TB_ATIVIDADES[[#This Row],[Esforço Total (min) '[=']]]-_xlpm.esforçoRealizado & IF(TB_ATIVIDADES[[#This Row],[Esforço Total (min) '[=']]]=0,""," (" & TEXT((TB_ATIVIDADES[[#This Row],[Esforço Total (min) '[=']]]-_xlpm.esforçoRealizado) / TB_ATIVIDADES[[#This Row],[Esforço Total (min) '[=']]],"0,0%") & ")"))) -> 105 (100,0%) | R16: =IF(OR(TB_ATIVIDADES[[#This Row],[Atividade '[*']]]="",TB_ATIVIDADES[[#This Row],[Fase '[*']]]=""),"-",_xlfn.LET(_xlpm.dataMin,_xlfn.MINIFS(TB_TAREFAS[Previsão Início '[*']],TB_TAREFAS[Atividade '[*']],TB_ATIVIDADES[[#This Row],[Atividade '[*']]]),IF(_xlpm.dataMin=0,"-",_xlpm.dataMin))) -> 46086 | S16: =IF(OR(TB_ATIVIDADES[[#This Row],[Atividade '[*']]]="",TB_ATIVIDADES[[#This Row],[Fase '[*']]]=""),"-",_xlfn.LET(_xlpm.dataMax,_xlfn.MAXIFS(TB_TAREFAS[Previsão Conclusão '[*']],TB_TAREFAS[Atividade '[*']],TB_ATIVIDADES[[#This Row],[Atividade '[*']]]),IF(_xlpm.dataMax=0,"-",_xlpm.dataMax))) -> 46086 | T16: =IF(OR(TB_ATIVIDADES[[#This Row],[Atividade '[*']]]="",TB_ATIVIDADES[[#This Row],[Fase '[*']]]=""),"-",IF(TB_ATIVIDADES[[#This Row],[Total Tarefas '[=']]]=0,"-",_xlfn.LET(_xlpm.totItensNaoConcluidos,COUNTIFS(TB_TAREFAS[Atividade '[*']],TB_ATIVIDADES[[#This Row],[Atividade '[*']]],TB_TAREFAS[Situação da Execução '[*']],"<>" & "CONCLUÍDA",TB_TAREFAS[Situação da Execução '[*']],"<>" & "DESNECESSÁRIA"),_xlpm.totItensConcluidos,TB_ATIVIDADES[[#This Row],[Total Tarefas '[=']]]-_xlpm.totItensNaoConcluidos,_xlpm.totItensNaoIniciados,COUNTIFS(TB_TAREFAS[Atividade '[*']],TB_ATIVIDADES[[#This Row],[Atividade '[*']]],TB_TAREFAS[Situação da Execução '[*']],"NÃO INICIADA"),IF(_xlpm.totItensConcluidos=TB_ATIVIDADES[[#This Row],[Total Tarefas '[=']]],"CONCLUÍDA",IF(_xlpm.totItensNaoIniciados=TB_ATIVIDADES[[#This Row],[Total Tarefas '[=']]],IF(AND(DATE(YEAR(NOW()),MONTH(NOW()),DAY(NOW())) > IFERROR(DATE(YEAR(TB_ATIVIDADES[[#This Row],[Previsão Início '[=']]]),MONTH(TB_ATIVIDADES[[#This Row],[Previsão Início '[=']]]),DAY(TB_ATIVIDADES[[#This Row],[Previsão Início '[=']]])),FALSE)),"INÍCIO COM ATRASO","NÃO INICIADA"),IF(AND(DATE(YEAR(NOW()),MONTH(NOW()),DAY(NOW())) > IFERROR(DATE(YEAR(TB_ATIVIDADES[[#This Row],[Previsão Conclusão '[=']]]),MONTH(TB_ATIVIDADES[[#This Row],[Previsão Conclusão '[=']]]),DAY(TB_ATIVIDADES[[#This Row],[Previsão Conclusão '[=']]])),FALSE)),"CONCLUSÃO COM ATRASO","EM ANDAMENTO")))))) -> INÍCIO COM ATRASO
